Workbook

Sheet Cases_Raw
A1: Case_ID | B1: Client | C1: Practice_Area | D1: Start_Date | E1: End_Date | F1: Budget_Hours | G1: Actual_Hours | H1: Standard_Rate | I1: Cost_Rate | J1: Budget_Fee | K1: Actual_Fee | M1: Synthetic data created for portfolio/interview demonstration purposes. Not actual BCG data
A2: C001 | B2: Alpha Health | C2: Financial Services | D2: 45678 | E2: 45858 | F2: 1092 | G2: 1441 | H2: 475 | I2: 250 | J2: 528000 | K2: 659000
A3: C002 | B3: Alpha Health | C3: Financial Services | D3: 45824 | E3: 45945 | F3: 891 | G3: 870 | H3: 475 | I3: 250 | J3: 430600 | K3: 402900
A4: C003 | B4: Alpha Health | C4: Technology | D4: 45931 | E4: 46030 | F4: 918 | G4: 935 | H4: 500 | I4: 270 | J4: 444100 | K4: 412500
A5: C004 | B5: Alpha Health | C5: Healthcare | D5: 46045 | E5: 46189 | F5: 788 | G5: 946 | H5: 450 | I5: 260 | J5: 349200 | K5: 382300
A6: C005 | B6: Gamma Energy | C6: Healthcare | D6: 45973 | E6: 46112 | F6: 878 | G6: 1134 | H6: 450 | I6: 260 | J6: 383700 | K6: 451200
A7: C006 | B7: Theta Health | C7: Financial Services | D7: 45671 | E7: 45839 | F7: 730 | G7: 827 | H7: 475 | I7: 250 | J7: 336300 | K7: 381200
A8: C007 | B8: Epsilon Tech | C8: Technology | D8: 45899 | E8: 46040 | F8: 1517 | G8: 1703 | H8: 500 | I8: 270 | J8: 722500 | K8: 770100
A9: C008 | B9: Epsilon Tech | C9: Financial Services | D9: 46003 | E9: 46173 | F9: 540 | G9: 568 | H9: 475 | I9: 250 | J9: 254600 | K9: 263500
A10: C009 | B10: Eta Consumer | C10: Financial Services | D10: 45997 | E10: 46109 | F10: 1551 | G10: 1562 | H10: 475 | I10: 250 | J10: 725800 | K10: 693100
A11: C010 | B11: Beta Bank | C11: Consumer | D11: 45749 | E11: 45832 | F11: 634 | G11: 590 | H11: 425 | I11: 235 | J11: 256900 | K11: 253500
A12: C011 | B12: Gamma Energy | C12: Consumer | D12: 46024 | E12: 46109 | F12: 700 | G12: 691 | H12: 425 | I12: 235 | J12: 288400 | K12: 264100
A13: C012 | B13: Eta Consumer | C13: Consumer | D13: 46112 | E13: 46260 | F13: 1279 | G13: 1419 | H13: 425 | I13: 235 | J13: 551000 | K13: 559500
... A31: C030 | B31: Delta Retail | C31: Financial Services | D31: 45909 | E31: 46083 | F31: 897 | G31: 921 | H31: 475 | I31: 250 | J31: 406000 | K31: 439300

Sheet Invoices_Raw
A1: Invoice_ID | B1: Case_ID | C1: Client | D1: Invoice_Date | E1: Amount | F1: Payment_Date | H1: Synthetic data created for portfolio/interview demonstration purposes. Not actual BCG data
A2: INV001 | B2: C003 | C2: Alpha Health | D2: 45959 | E2: 223300 | F2: 46035
A3: INV002 | B3: C004 | C3: Alpha Health | D3: 46058 | E3: 191600 | F3: 46125
A4: INV003 | B4: C001 | C4: Alpha Health | D4: 45698 | E4: 329600
A5: INV004 | B5: C004 | C5: Alpha Health | D5: 46050 | E5: 202600 | F5: 46147
A6: INV005 | B6: C001 | C6: Alpha Health | D6: 45680 | E6: 339400 | F6: 45784
A7: INV006 | B7: C004 | C7: Alpha Health | D7: 46072 | E7: 198900
A8: INV007 | B8: C004 | C8: Alpha Health | D8: 46053 | E8: 202500 | F8: 46160
A9: INV008 | B9: C002 | C9: Alpha Health | D9: 45828 | E9: 217200 | F9: 45936
A10: INV009 | B10: C014 | C10: Gamma Energy | D10: 46189 | E10: 386100 | F10: 46208
A11: INV010 | B11: C018 | C11: Theta Health | D11: 46073 | E11: 288900 | F11: 46099
A12: INV011 | B12: C002 | C12: Alpha Health | D12: 45840 | E12: 185100 | F12: 45933
A13: INV012 | B13: C022 | C13: Epsilon Tech | D13: 46147 | E13: 354000 | F13: 46187
A14: INV013 | B14: C003 | C14: Alpha Health | D14: 45951 | E14: 187100 | F14: 46028
A15: INV014 | B15: C016 | C15: Epsilon Tech | D15: 45893 | E15: 260400 | F15: 45955
A16: INV015 | B16: C029 | C16: Theta Health | D16: 46121 | E16: 277800 | F16: 46156
A17: INV016 | B17: C009 | C17: Eta Consumer | D17: 46024 | E17: 331800 | F17: 46077
A18: INV017 | B18: C004 | C18: Alpha Health | D18: 46045 | E18: 194600 | F18: 46121
A19: INV018 | B19: C001 | C19: Alpha Health | D19: 45697 | E19: 298600 | F19: 45792
... A26: INV025 | B26: C024 | C26: Theta Health | D26: 45836 | E26: 480600 | F26: 45855
A27: INV026 | B27: C008 | C27: Epsilon Tech | D27: 46027 | E27: 135000
A28: INV027 | B28: C007 | C28: Epsilon Tech | D28: 45908 | E28: 353100 | F28: 45956
A29: INV028 | B29: C003 | C29: Alpha Health | D29: 45961 | E29: 187800 | F29: 46076
A30: INV029 | B30: C017 | C30: Delta Retail | D30: 45759 | E30: 237300 | F30: 45804
A31: INV030 | B31: C001 | C31: Alpha Health | D31: 45703 | E31: 332200 | F31: 45817
A32: INV031 | B32: C016 | C32: Epsilon Tech | D32: 45865 | E32: 269500 | F32: 45937
A33: INV032 | B33: C012 | C33: Eta Consumer | D33: 46119 | E33: 292400 | F33: 46152
A34: INV033 | B34: C027 | C34: Zeta Financial | D34: 45941 | E34: 370800
A35: INV034 | B35: C019 | C35: Theta Health | D35: 45682 | E35: 138600 | F35: 45728
A36: INV035 | B36: C022 | C36: Epsilon Tech | D36: 46151 | E36: 336200
A37: INV036 | B37: C023 | C37: Beta Bank | D37: 46073 | E37: 259100 | F37: 46143
A38: INV037 | B38: C022 | C38: Epsilon Tech | D38: 46155 | E38: 332600 | F38: 46174
A39: INV038 | B39: C014 | C39: Gamma Energy | D39: 46188 | E39: 394100 | F39: 46247
A40: INV039 | B40: C030 | C40: Delta Retail | D40: 45910 | E40: 201100 | F40: 45928
A41: INV040 | B41: C006 | C41: Theta Health | D41: 45701 | E41: 172500 | F41: 45731
A42: INV041 | B42: C006 | C42: Theta Health | D42: 45697 | E42: 208200 | F42: 45735
A43: INV042 | B43: C013 | C43: Gamma Energy | D43: 46094 | E43: 340800 | F43: 46124
A44: INV043 | B44: C019 | C44: Theta Health | D44: 45660 | E44: 143500 | F44: 45729
A45: INV044 | B45: C022 | C45: Epsilon Tech | D45: 46159 | E45: 342200 | F45: 46175
A46: INV045 | B46: C008 | C46: Epsilon Tech | D46: 46019 | E46: 123100 | F46: 46082
...

Sheet Calculations
A1: Case_ID | B1: Client | C1: Practice Area | D1: Budget Hours | E1: Actual Hours | F1: Hours Variance % | G1: Budget Fee | H1: Actual Fee | I1: Fee Variance % | J1: Standard Rate Value | K1: Realization | L1: Cost Rate | M1: Labor Cost | N1: Gross Profit | O1: Gross Margin | Q1: Invoice_ID | R1: Case_ID | S1: Client | T1: Invoice_Date | U1: Amount | V1: Payment_Date | W1: Payment_Status | X1: Days_Outstanding | Y1: Aging_Bucket
A2: =Cases_Raw!A2 -> C001 | B2: =Cases_Raw!B2 -> Alpha Health | C2: =Cases_Raw!C2 -> Financial Services | D2: =Cases_Raw!F2 -> 1092 | E2: =Cases_Raw!G2 -> 1441 | F2: =(E2-D2)/D2 -> 0.31959707 | G2: =Cases_Raw!J2 -> 528000 | H2: =Cases_Raw!K2 -> 659000 | I2: =(H2-G2)/G2 -> 0.24810606 | J2: =E2*_xlfn.XLOOKUP(A2,Cases[Case_ID],Cases[Standard_Rate]) -> 684475 | K2: =H2/J2 -> 0.96278169 | L2: =Cases_Raw!I2 -> 250 | M2: =E2*L2 -> 360250 | N2: =H2-M2 -> 298750 | O2: =N2/H2 -> 0.45333839 | Q2: =Invoices_Raw!A2 -> INV001 | R2: =Invoices_Raw!B2 -> C003 | S2: =Invoices_Raw!C2 -> Alpha Health | T2: =Invoices_Raw!D2 -> 45959 | U2: =Invoices_Raw!E2 -> 223300 | V2: =Invoices_Raw!F2 -> 46035 | W2: =IF(V2="","Unpaid","Paid") -> Paid | X2: =IF(V2<>"",V2-T2,$B$2-T2) -> 76 | Y2: =IF(X2<=30,"0-30", IF(X2<=60,"31-60", IF(X2<=90,"61-90","90+"))) -> 61-90
A3: =Cases_Raw!A3 -> C002 | B3: =Cases_Raw!B3 -> Alpha Health | C3: =Cases_Raw!C3 -> Financial Services | D3: =Cases_Raw!F3 -> 891 | E3: =Cases_Raw!G3 -> 870 | F3: =(E3-D3)/D3 -> -0.023569024 | G3: =Cases_Raw!J3 -> 430600 | H3: =Cases_Raw!K3 -> 402900 | I3: =(H3-G3)/G3 -> -0.064328843 | J3: =E3*_xlfn.XLOOKUP(A3,Cases[Case_ID],Cases[Standard_Rate]) -> 413250 | K3: =H3/J3 -> 0.97495463 | L3: =Cases_Raw!I3 -> 250 | M3: =E3*L3 -> 217500 | N3: =H3-M3 -> 185400 | O3: =N3/H3 -> 0.46016381 | Q3: =Invoices_Raw!A3 -> INV002 | R3: =Invoices_Raw!B3 -> C004 | S3: =Invoices_Raw!C3 -> Alpha Health | T3: =Invoices_Raw!D3 -> 46058 | U3: =Invoices_Raw!E3 -> 191600 | V3: =Invoices_Raw!F3 -> 46125 | W3: =IF(V3="","Unpaid","Paid") -> Paid | X3: =IF(V3<>"",V3-T3,Summary!$B$1-T3) -> 67 | Y3: =IF(X3<=30,"0-30", IF(X3<=60,"31-60", IF(X3<=90,"61-90","90+"))) -> 61-90
A4: =Cases_Raw!A4 -> C003 | B4: =Cases_Raw!B4 -> Alpha Health | C4: =Cases_Raw!C4 -> Technology | D4: =Cases_Raw!F4 -> 918 | E4: =Cases_Raw!G4 -> 935 | F4: =(E4-D4)/D4 -> 0.018518519 | G4: =Cases_Raw!J4 -> 444100 | H4: =Cases_Raw!K4 -> 412500 | I4: =(H4-G4)/G4 -> -0.071155145 | J4: =E4*_xlfn.XLOOKUP(A4,Cases[Case_ID],Cases[Standard_Rate]) -> 467500 | K4: =H4/J4 -> 0.88235294 | L4: =Cases_Raw!I4 -> 270 | M4: =E4*L4 -> 252450 | N4: =H4-M4 -> 160050 | O4: =N4/H4 -> 0.388 | Q4: =Invoices_Raw!A4 -> INV003 | R4: =Invoices_Raw!B4 -> C001 | S4: =Invoices_Raw!C4 -> Alpha Health | T4: =Invoices_Raw!D4 -> 45698 | U4: =Invoices_Raw!E4 -> 329600 | W4: =IF(V4="","Unpaid","Paid") -> Unpaid | X4: =IF(V4<>"",V4-T4,Summary!$B$1-T4) -> 689 | Y4: =IF(X4<=30,"0-30", IF(X4<=60,"31-60", IF(X4<=90,"61-90","90+"))) -> 90+
A5: =Cases_Raw!A5 -> C004 | B5: =Cases_Raw!B5 -> Alpha Health | C5: =Cases_Raw!C5 -> Healthcare | D5: =Cases_Raw!F5 -> 788 | E5: =Cases_Raw!G5 -> 946 | F5: =(E5-D5)/D5 -> 0.20050761 | G5: =Cases_Raw!J5 -> 349200 | H5: =Cases_Raw!K5 -> 382300 | I5: =(H5-G5)/G5 -> 0.094788087 | J5: =E5*_xlfn.XLOOKUP(A5,Cases[Case_ID],Cases[Standard_Rate]) -> 425700 | K5: =H5/J5 -> 0.89805027 | L5: =Cases_Raw!I5 -> 260 | M5: =E5*L5 -> 245960 | N5: =H5-M5 -> 136340 | O5: =N5/H5 -> 0.35663092 | Q5: =Invoices_Raw!A5 -> INV004 | R5: =Invoices_Raw!B5 -> C004 | S5: =Invoices_Raw!C5 -> Alpha Health | T5: =Invoices_Raw!D5 -> 46050 | U5: =Invoices_Raw!E5 -> 202600 | V5: =Invoices_Raw!F5 -> 46147 | W5: =IF(V5="","Unpaid","Paid") -> Paid | X5: =IF(V5<>"",V5-T5,Summary!$B$1-T5) -> 97 | Y5: =IF(X5<=30,"0-30", IF(X5<=60,"31-60", IF(X5<=90,"61-90","90+"))) -> 90+
A6: =Cases_Raw!A6 -> C005 | B6: =Cases_Raw!B6 -> Gamma Energy | C6: =Cases_Raw!C6 -> Healthcare | D6: =Cases_Raw!F6 -> 878 | E6: =Cases_Raw!G6 -> 1134 | F6: =(E6-D6)/D6 -> 0.29157175 | G6: =Cases_Raw!J6 -> 383700 | H6: =Cases_Raw!K6 -> 451200 | I6: =(H6-G6)/G6 -> 0.17591869 | J6: =E6*_xlfn.XLOOKUP(A6,Cases[Case_ID],Cases[Standard_Rate]) -> 510300 | K6: =H6/J6 -> 0.88418577 | L6: =Cases_Raw!I6 -> 260 | M6: =E6*L6 -> 294840 | N6: =H6-M6 -> 156360 | O6: =N6/H6 -> 0.34654255 | Q6: =Invoices_Raw!A6 -> INV005 | R6: =Invoices_Raw!B6 -> C001 | S6: =Invoices_Raw!C6 -> Alpha Health | T6: =Invoices_Raw!D6 -> 45680 | U6: =Invoices_Raw!E6 -> 339400 | V6: =Invoices_Raw!F6 -> 45784 | W6: =IF(V6="","Unpaid","Paid") -> Paid | X6: =IF(V6<>"",V6-T6,Summary!$B$1-T6) -> 104 | Y6: =IF(X6<=30,"0-30", IF(X6<=60,"31-60", IF(X6<=90,"61-90","90+"))) -> 90+
A7: =Cases_Raw!A7 -> C006 | B7: =Cases_Raw!B7 -> Theta Health | C7: =Cases_Raw!C7 -> Financial Services | D7: =Cases_Raw!F7 -> 730 | E7: =Cases_Raw!G7 -> 827 | F7: =(E7-D7)/D7 -> 0.13287671 | G7: =Cases_Raw!J7 -> 336300 | H7: =Cases_Raw!K7 -> 381200 | I7: =(H7-G7)/G7 -> 0.13351175 | J7: =E7*_xlfn.XLOOKUP(A7,Cases[Case_ID],Cases[Standard_Rate]) -> 392825 | K7: =H7/J7 -> 0.97040667 | L7: =Cases_Raw!I7 -> 250 | M7: =E7*L7 -> 206750 | N7: =H7-M7 -> 174450 | O7: =N7/H7 -> 0.45763379 | Q7: =Invoices_Raw!A7 -> INV006 | R7: =Invoices_Raw!B7 -> C004 | S7: =Invoices_Raw!C7 -> Alpha Health | T7: =Invoices_Raw!D7 -> 46072 | U7: =Invoices_Raw!E7 -> 198900 | W7: =IF(V7="","Unpaid","Paid") -> Unpaid | X7: =IF(V7<>"",V7-T7,Summary!$B$1-T7) -> 315 | Y7: =IF(X7<=30,"0-30", IF(X7<=60,"31-60", IF(X7<=90,"61-90","90+"))) -> 90+
A8: =Cases_Raw!A8 -> C007 | B8: =Cases_Raw!B8 -> Epsilon Tech | C8: =Cases_Raw!C8 -> Technology | D8: =Cases_Raw!F8 -> 1517 | E8: =Cases_Raw!G8 -> 1703 | F8: =(E8-D8)/D8 -> 0.12261042 | G8: =Cases_Raw!J8 -> 722500 | H8: =Cases_Raw!K8 -> 770100 | I8: =(H8-G8)/G8 -> 0.065882353 | J8: =E8*_xlfn.XLOOKUP(A8,Cases[Case_ID],Cases[Standard_Rate]) -> 851500 | K8: =H8/J8 -> 0.90440399 | L8: =Cases_Raw!I8 -> 270 | M8: =E8*L8 -> 459810 | N8: =H8-M8 -> 310290 | O8: =N8/H8 -> 0.4029217 | Q8: =Invoices_Raw!A8 -> INV007 | R8: =Invoices_Raw!B8 -> C004 | S8: =Invoices_Raw!C8 -> Alpha Health | T8: =Invoices_Raw!D8 -> 46053 | U8: =Invoices_Raw!E8 -> 202500 | V8: =Invoices_Raw!F8 -> 46160 | W8: =IF(V8="","Unpaid","Paid") -> Paid | X8: =IF(V8<>"",V8-T8,Summary!$B$1-T8) -> 107 | Y8: =IF(X8<=30,"0-30", IF(X8<=60,"31-60", IF(X8<=90,"61-90","90+"))) -> 90+
A9: =Cases_Raw!A9 -> C008 | B9: =Cases_Raw!B9 -> Epsilon Tech | C9: =Cases_Raw!C9 -> Financial Services | D9: =Cases_Raw!F9 -> 540 | E9: =Cases_Raw!G9 -> 568 | F9: =(E9-D9)/D9 -> 0.051851852 | G9: =Cases_Raw!J9 -> 254600 | H9: =Cases_Raw!K9 -> 263500 | I9: =(H9-G9)/G9 -> 0.034956795 | J9: =E9*_xlfn.XLOOKUP(A9,Cases[Case_ID],Cases[Standard_Rate]) -> 269800 | K9: =H9/J9 -> 0.97664937 | L9: =Cases_Raw!I9 -> 250 | M9: =E9*L9 -> 142000 | N9: =H9-M9 -> 121500 | O9: =N9/H9 -> 0.46110057 | Q9: =Invoices_Raw!A9 -> INV008 | R9: =Invoices_Raw!B9 -> C002 | S9: =Invoices_Raw!C9 -> Alpha Health | T9: =Invoices_Raw!D9 -> 45828 | U9: =Invoices_Raw!E9 -> 217200 | V9: =Invoices_Raw!F9 -> 45936 | W9: =IF(V9="","Unpaid","Paid") -> Paid | X9: =IF(V9<>"",V9-T9,Summary!$B$1-T9) -> 108 | Y9: =IF(X9<=30,"0-30", IF(X9<=60,"31-60", IF(X9<=90,"61-90","90+"))) -> 90+
A10: =Cases_Raw!A10 -> C009 | B10: =Cases_Raw!B10 -> Eta Consumer | C10: =Cases_Raw!C10 -> Financial Services | D10: =Cases_Raw!F10 -> 1551 | E10: =Cases_Raw!G10 -> 1562 | F10: =(E10-D10)/D10 -> 0.0070921986 | G10: =Cases_Raw!J10 -> 725800 | H10: =Cases_Raw!K10 -> 693100 | I10: =(H10-G10)/G10 -> -0.045053734 | J10: =E10*_xlfn.XLOOKUP(A10,Cases[Case_ID],Cases[Standard_Rate]) -> 741950 | K10: =H10/J10 -> 0.93415998 | L10: =Cases_Raw!I10 -> 250 | M10: =E10*L10 -> 390500 | N10: =H10-M10 -> 302600 | O10: =N10/H10 -> 0.43658924 | Q10: =Invoices_Raw!A10 -> INV009 | R10: =Invoices_Raw!B10 -> C014 | S10: =Invoices_Raw!C10 -> Gamma Energy | T10: =Invoices_Raw!D10 -> 46189 | U10: =Invoices_Raw!E10 -> 386100 | V10: =Invoices_Raw!F10 -> 46208 | W10: =IF(V10="","Unpaid","Paid") -> Paid | X10: =IF(V10<>"",V10-T10,Summary!$B$1-T10) -> 19 | Y10: =IF(X10<=30,"0-30", IF(X10<=60,"31-60", IF(X10<=90,"61-90","90+"))) -> 0-30
A11: =Cases_Raw!A11 -> C010 | B11: =Cases_Raw!B11 -> Beta Bank | C11: =Cases_Raw!C11 -> Consumer | D11: =Cases_Raw!F11 -> 634 | E11: =Cases_Raw!G11 -> 590 | F11: =(E11-D11)/D11 -> -0.069400631 | G11: =Cases_Raw!J11 -> 256900 | H11: =Cases_Raw!K11 -> 253500 | I11: =(H11-G11)/G11 -> -0.013234722 | J11: =E11*_xlfn.XLOOKUP(A11,Cases[Case_ID],Cases[Standard_Rate]) -> 250750 | K11: =H11/J11 -> 1.0109671 | L11: =Cases_Raw!I11 -> 235 | M11: =E11*L11 -> 138650 | N11: =H11-M11 -> 114850 | O11: =N11/H11 -> 0.4530572 | Q11: =Invoices_Raw!A11 -> INV010 | R11: =Invoices_Raw!B11 -> C018 | S11: =Invoices_Raw!C11 -> Theta Health | T11: =Invoices_Raw!D11 -> 46073 | U11: =Invoices_Raw!E11 -> 288900 | V11: =Invoices_Raw!F11 -> 46099 | W11: =IF(V11="","Unpaid","Paid") -> Paid | X11: =IF(V11<>"",V11-T11,Summary!$B$1-T11) -> 26 | Y11: =IF(X11<=30,"0-30", IF(X11<=60,"31-60", IF(X11<=90,"61-90","90+"))) -> 0-30
A12: =Cases_Raw!A12 -> C011 | B12: =Cases_Raw!B12 -> Gamma Energy | C12: =Cases_Raw!C12 -> Consumer | D12: =Cases_Raw!F12 -> 700 | E12: =Cases_Raw!G12 -> 691 | F12: =(E12-D12)/D12 -> -0.012857143 | G12: =Cases_Raw!J12 -> 288400 | H12: =Cases_Raw!K12 -> 264100 | I12: =(H12-G12)/G12 -> -0.084257975 | J12: =E12*_xlfn.XLOOKUP(A12,Cases[Case_ID],Cases[Standard_Rate]) -> 293675 | K12: =H12/J12 -> 0.89929344 | L12: =Cases_Raw!I12 -> 235 | M12: =E12*L12 -> 162385 | N12: =H12-M12 -> 101715 | O12: =N12/H12 -> 0.38513821 | Q12: =Invoices_Raw!A12 -> INV011 | R12: =Invoices_Raw!B12 -> C002 | S12: =Invoices_Raw!C12 -> Alpha Health | T12: =Invoices_Raw!D12 -> 45840 | U12: =Invoices_Raw!E12 -> 185100 | V12: =Invoices_Raw!F12 -> 45933 | W12: =IF(V12="","Unpaid","Paid") -> Paid | X12: =IF(V12<>"",V12-T12,Summary!$B$1-T12) -> 93 | Y12: =IF(X12<=30,"0-30", IF(X12<=60,"31-60", IF(X12<=90,"61-90","90+"))) -> 90+
A13: =Cases_Raw!A13 -> C012 | B13: =Cases_Raw!B13 -> Eta Consumer | C13: =Cases_Raw!C13 -> Consumer | D13: =Cases_Raw!F13 -> 1279 | E13: =Cases_Raw!G13 -> 1419 | F13: =(E13-D13)/D13 -> 0.10946052 | G13: =Cases_Raw!J13 -> 551000 | H13: =Cases_Raw!K13 -> 559500 | I13: =(H13-G13)/G13 -> 0.015426497 | J13: =E13*_xlfn.XLOOKUP(A13,Cases[Case_ID],Cases[Standard_Rate]) -> 603075 | K13: =H13/J13 -> 0.92774531 | L13: =Cases_Raw!I13 -> 235 | M13: =E13*L13 -> 333465 | N13: =H13-M13 -> 226035 | O13: =N13/H13 -> 0.40399464 | Q13: =Invoices_Raw!A13 -> INV012 | R13: =Invoices_Raw!B13 -> C022 | S13: =Invoices_Raw!C13 -> Epsilon Tech | T13: =Invoices_Raw!D13 -> 46147 | U13: =Invoices_Raw!E13 -> 354000 | V13: =Invoices_Raw!F13 -> 46187 | W13: =IF(V13="","Unpaid","Paid") -> Paid | X13: =IF(V13<>"",V13-T13,Summary!$B$1-T13) -> 40 | Y13: =IF(X13<=30,"0-30", IF(X13<=60,"31-60", IF(X13<=90,"61-90","90+"))) -> 31-60
A14: =Cases_Raw!A14 -> C013 | B14: =Cases_Raw!B14 -> Gamma Energy | C14: =Cases_Raw!C14 -> Healthcare | D14: =Cases_Raw!F14 -> 1429 | E14: =Cases_Raw!G14 -> 1713 | F14: =(E14-D14)/D14 -> 0.19874038 | G14: =Cases_Raw!J14 -> 621700 | H14: =Cases_Raw!K14 -> 638600 | I14: =(H14-G14)/G14 -> 0.027183529 | J14: =E14*_xlfn.XLOOKUP(A14,Cases[Case_ID],Cases[Standard_Rate]) -> 770850 | K14: =H14/J14 -> 0.82843614 | L14: =Cases_Raw!I14 -> 260 | M14: =E14*L14 -> 445380 | N14: =H14-M14 -> 193220 | O14: =N14/H14 -> 0.30256812 | Q14: =Invoices_Raw!A14 -> INV013 | R14: =Invoices_Raw!B14 -> C003 | S14: =Invoices_Raw!C14 -> Alpha Health | T14: =Invoices_Raw!D14 -> 45951 | U14: =Invoices_Raw!E14 -> 187100 | V14: =Invoices_Raw!F14 -> 46028 | W14: =IF(V14="","Unpaid","Paid") -> Paid | X14: =IF(V14<>"",V14-T14,Summary!$B$1-T14) -> 77 | Y14: =IF(X14<=30,"0-30", IF(X14<=60,"31-60", IF(X14<=90,"61-90","90+"))) -> 61-90
A15: =Cases_Raw!A15 -> C014 | B15: =Cases_Raw!B15 -> Gamma Energy | C15: =Cases_Raw!C15 -> Technology | D15: =Cases_Raw!F15 -> 1556 | E15: =Cases_Raw!G15 -> 1581 | F15: =(E15-D15)/D15 -> 0.016066838 | G15: =Cases_Raw!J15 -> 747000 | H15: =Cases_Raw!K15 -> 798000 | I15: =(H15-G15)/G15 -> 0.068273092 | J15: =E15*_xlfn.XLOOKUP(A15,Cases[Case_ID],Cases[Standard_Rate]) -> 790500 | K15: =H15/J15 -> 1.0094877 | L15: =Cases_Raw!I15 -> 270 | M15: =E15*L15 -> 426870 | N15: =H15-M15 -> 371130 | O15: =N15/H15 -> 0.46507519 | Q15: =Invoices_Raw!A15 -> INV014 | R15: =Invoices_Raw!B15 -> C016 | S15: =Invoices_Raw!C15 -> Epsilon Tech | T15: =Invoices_Raw!D15 -> 45893 | U15: =Invoices_Raw!E15 -> 260400 | V15: =Invoices_Raw!F15 -> 45955 | W15: =IF(V15="","Unpaid","Paid") -> Paid | X15: =IF(V15<>"",V15-T15,Summary!$B$1-T15) -> 62 | Y15: =IF(X15<=30,"0-30", IF(X15<=60,"31-60", IF(X15<=90,"61-90","90+"))) -> 61-90
A16: =Cases_Raw!A16 -> C015 | B16: =Cases_Raw!B16 -> Theta Health | C16: =Cases_Raw!C16 -> Technology | D16: =Cases_Raw!F16 -> 1571 | E16: =Cases_Raw!G16 -> 1713 | F16: =(E16-D16)/D16 -> 0.090388288 | G16: =Cases_Raw!J16 -> 773100 | H16: =Cases_Raw!K16 -> 858900 | I16: =(H16-G16)/G16 -> 0.11098176 | J16: =E16*_xlfn.XLOOKUP(A16,Cases[Case_ID],Cases[Standard_Rate]) -> 856500 | K16: =H16/J16 -> 1.0028021 | L16: =Cases_Raw!I16 -> 270 | M16: =E16*L16 -> 462510 | N16: =H16-M16 -> 396390 | O16: =N16/H16 -> 0.46150891 | Q16: =Invoices_Raw!A16 -> INV015 | R16: =Invoices_Raw!B16 -> C029 | S16: =Invoices_Raw!C16 -> Theta Health | T16: =Invoices_Raw!D16 -> 46121 | U16: =Invoices_Raw!E16 -> 277800 | V16: =Invoices_Raw!F16 -> 46156 | W16: =IF(V16="","Unpaid","Paid") -> Paid | X16: =IF(V16<>"",V16-T16,Summary!$B$1-T16) -> 35 | Y16: =IF(X16<=30,"0-30", IF(X16<=60,"31-60", IF(X16<=90,"61-90","90+"))) -> 31-60
A17: =Cases_Raw!A17 -> C016 | B17: =Cases_Raw!B17 -> Epsilon Tech | C17: =Cases_Raw!C17 -> Technology | D17: =Cases_Raw!F17 -> 1002 | E17: =Cases_Raw!G17 -> 1145 | F17: =(E17-D17)/D17 -> 0.14271457 | G17: =Cases_Raw!J17 -> 510500 | H17: =Cases_Raw!K17 -> 524500 | I17: =(H17-G17)/G17 -> 0.027424094 | J17: =E17*_xlfn.XLOOKUP(A17,Cases[Case_ID],Cases[Standard_Rate]) -> 572500 | K17: =H17/J17 -> 0.91615721 | L17: =Cases_Raw!I17 -> 270 | M17: =E17*L17 -> 309150 | N17: =H17-M17 -> 215350 | O17: =N17/H17 -> 0.41058151 | Q17: =Invoices_Raw!A17 -> INV016 | R17: =Invoices_Raw!B17 -> C009 | S17: =Invoices_Raw!C17 -> Eta Consumer | T17: =Invoices_Raw!D17 -> 46024 | U17: =Invoices_Raw!E17 -> 331800 | V17: =Invoices_Raw!F17 -> 46077 | W17: =IF(V17="","Unpaid","Paid") -> Paid | X17: =IF(V17<>"",V17-T17,Summary!$B$1-T17) -> 53 | Y17: =IF(X17<=30,"0-30", IF(X17<=60,"31-60", IF(X17<=90,"61-90","90+"))) -> 31-60
A18: =Cases_Raw!A18 -> C017 | B18: =Cases_Raw!B18 -> Delta Retail | C18: =Cases_Raw!C18 -> Technology | D18: =Cases_Raw!F18 -> 906 | E18: =Cases_Raw!G18 -> 970 | F18: =(E18-D18)/D18 -> 0.070640177 | G18: =Cases_Raw!J18 -> 438000 | H18: =Cases_Raw!K18 -> 471600 | I18: =(H18-G18)/G18 -> 0.076712329 | J18: =E18*_xlfn.XLOOKUP(A18,Cases[Case_ID],Cases[Standard_Rate]) -> 485000 | K18: =H18/J18 -> 0.97237113 | L18: =Cases_Raw!I18 -> 270 | M18: =E18*L18 -> 261900 | N18: =H18-M18 -> 209700 | O18: =N18/H18 -> 0.44465649 | Q18: =Invoices_Raw!A18 -> INV017 | R18: =Invoices_Raw!B18 -> C004 | S18: =Invoices_Raw!C18 -> Alpha Health | T18: =Invoices_Raw!D18 -> 46045 | U18: =Invoices_Raw!E18 -> 194600 | V18: =Invoices_Raw!F18 -> 46121 | W18: =IF(V18="","Unpaid","Paid") -> Paid | X18: =IF(V18<>"",V18-T18,Summary!$B$1-T18) -> 76 | Y18: =IF(X18<=30,"0-30", IF(X18<=60,"31-60", IF(X18<=90,"61-90","90+"))) -> 61-90
A19: =Cases_Raw!A19 -> C018 | B19: =Cases_Raw!B19 -> Theta Health | C19: =Cases_Raw!C19 -> Consumer | D19: =Cases_Raw!F19 -> 1304 | E19: =Cases_Raw!G19 -> 1402 | F19: =(E19-D19)/D19 -> 0.075153374 | G19: =Cases_Raw!J19 -> 552600 | H19: =Cases_Raw!K19 -> 592500 | I19: =(H19-G19)/G19 -> 0.072204126 | J19: =E19*_xlfn.XLOOKUP(A19,Cases[Case_ID],Cases[Standard_Rate]) -> 595850 | K19: =H19/J19 -> 0.99437778 | L19: =Cases_Raw!I19 -> 235 | M19: =E19*L19 -> 329470 | N19: =H19-M19 -> 263030 | O19: =N19/H19 -> 0.44393249 | Q19: =Invoices_Raw!A19 -> INV018 | R19: =Invoices_Raw!B19 -> C001 | S19: =Invoices_Raw!C19 -> Alpha Health | T19: =Invoices_Raw!D19 -> 45697 | U19: =Invoices_Raw!E19 -> 298600 | V19: =Invoices_Raw!F19 -> 45792 | W19: =IF(V19="","Unpaid","Paid") -> Paid | X19: =IF(V19<>"",V19-T19,Summary!$B$1-T19) -> 95 | Y19: =IF(X19<=30,"0-30", IF(X19<=60,"31-60", IF(X19<=90,"61-90","90+"))) -> 90+
... A26: =Cases_Raw!A26 -> C025 | B26: =Cases_Raw!B26 -> Delta Retail | C26: =Cases_Raw!C26 -> Consumer | D26: =Cases_Raw!F26 -> 1142 | E26: =Cases_Raw!G26 -> 1315 | F26: =(E26-D26)/D26 -> 0.15148862 | G26: =Cases_Raw!J26 -> 479300 | H26: =Cases_Raw!K26 -> 541300 | I26: =(H26-G26)/G26 -> 0.12935531 | J26: =E26*_xlfn.XLOOKUP(A26,Cases[Case_ID],Cases[Standard_Rate]) -> 558875 | K26: =H26/J26 -> 0.9685529 | L26: =Cases_Raw!I26 -> 235 | M26: =E26*L26 -> 309025 | N26: =H26-M26 -> 232275 | O26: =N26/H26 -> 0.42910586 | Q26: =Invoices_Raw!A26 -> INV025 | R26: =Invoices_Raw!B26 -> C024 | S26: =Invoices_Raw!C26 -> Theta Health | T26: =Invoices_Raw!D26 -> 45836 | U26: =Invoices_Raw!E26 -> 480600 | V26: =Invoices_Raw!F26 -> 45855 | W26: =IF(V26="","Unpaid","Paid") -> Paid | X26: =IF(V26<>"",V26-T26,Summary!$B$1-T26) -> 19 | Y26: =IF(X26<=30,"0-30", IF(X26<=60,"31-60", IF(X26<=90,"61-90","90+"))) -> 0-30
A27: =Cases_Raw!A27 -> C026 | B27: =Cases_Raw!B27 -> Zeta Financial | C27: =Cases_Raw!C27 -> Technology | D27: =Cases_Raw!F27 -> 1528 | E27: =Cases_Raw!G27 -> 1569 | F27: =(E27-D27)/D27 -> 0.026832461 | G27: =Cases_Raw!J27 -> 730600 | H27: =Cases_Raw!K27 -> 727600 | I27: =(H27-G27)/G27 -> -0.0041062141 | J27: =E27*_xlfn.XLOOKUP(A27,Cases[Case_ID],Cases[Standard_Rate]) -> 784500 | K27: =H27/J27 -> 0.92746973 | L27: =Cases_Raw!I27 -> 270 | M27: =E27*L27 -> 423630 | N27: =H27-M27 -> 303970 | O27: =N27/H27 -> 0.41777075 | Q27: =Invoices_Raw!A27 -> INV026 | R27: =Invoices_Raw!B27 -> C008 | S27: =Invoices_Raw!C27 -> Epsilon Tech | T27: =Invoices_Raw!D27 -> 46027 | U27: =Invoices_Raw!E27 -> 135000 | W27: =IF(V27="","Unpaid","Paid") -> Unpaid | X27: =IF(V27<>"",V27-T27,Summary!$B$1-T27) -> 360 | Y27: =IF(X27<=30,"0-30", IF(X27<=60,"31-60", IF(X27<=90,"61-90","90+"))) -> 90+
A28: =Cases_Raw!A28 -> C027 | B28: =Cases_Raw!B28 -> Zeta Financial | C28: =Cases_Raw!C28 -> Technology | D28: =Cases_Raw!F28 -> 1741 | E28: =Cases_Raw!G28 -> 1458 | F28: =(E28-D28)/D28 -> -0.16255026 | G28: =Cases_Raw!J28 -> 877900 | H28: =Cases_Raw!K28 -> 677200 | I28: =(H28-G28)/G28 -> -0.22861374 | J28: =E28*_xlfn.XLOOKUP(A28,Cases[Case_ID],Cases[Standard_Rate]) -> 729000 | K28: =H28/J28 -> 0.92894376 | L28: =Cases_Raw!I28 -> 270 | M28: =E28*L28 -> 393660 | N28: =H28-M28 -> 283540 | O28: =N28/H28 -> 0.41869462 | Q28: =Invoices_Raw!A28 -> INV027 | R28: =Invoices_Raw!B28 -> C007 | S28: =Invoices_Raw!C28 -> Epsilon Tech | T28: =Invoices_Raw!D28 -> 45908 | U28: =Invoices_Raw!E28 -> 353100 | V28: =Invoices_Raw!F28 -> 45956 | W28: =IF(V28="","Unpaid","Paid") -> Paid | X28: =IF(V28<>"",V28-T28,Summary!$B$1-T28) -> 48 | Y28: =IF(X28<=30,"0-30", IF(X28<=60,"31-60", IF(X28<=90,"61-90","90+"))) -> 31-60
A29: =Cases_Raw!A29 -> C028 | B29: =Cases_Raw!B29 -> Beta Bank | C29: =Cases_Raw!C29 -> Financial Services | D29: =Cases_Raw!F29 -> 1002 | E29: =Cases_Raw!G29 -> 1080 | F29: =(E29-D29)/D29 -> 0.077844311 | G29: =Cases_Raw!J29 -> 462800 | H29: =Cases_Raw!K29 -> 503600 | I29: =(H29-G29)/G29 -> 0.088159032 | J29: =E29*_xlfn.XLOOKUP(A29,Cases[Case_ID],Cases[Standard_Rate]) -> 513000 | K29: =H29/J29 -> 0.98167641 | L29: =Cases_Raw!I29 -> 250 | M29: =E29*L29 -> 270000 | N29: =H29-M29 -> 233600 | O29: =N29/H29 -> 0.46386021 | Q29: =Invoices_Raw!A29 -> INV028 | R29: =Invoices_Raw!B29 -> C003 | S29: =Invoices_Raw!C29 -> Alpha Health | T29: =Invoices_Raw!D29 -> 45961 | U29: =Invoices_Raw!E29 -> 187800 | V29: =Invoices_Raw!F29 -> 46076 | W29: =IF(V29="","Unpaid","Paid") -> Paid | X29: =IF(V29<>"",V29-T29,Summary!$B$1-T29) -> 115 | Y29: =IF(X29<=30,"0-30", IF(X29<=60,"31-60", IF(X29<=90,"61-90","90+"))) -> 90+
A30: =Cases_Raw!A30 -> C029 | B30: =Cases_Raw!B30 -> Theta Health | C30: =Cases_Raw!C30 -> Consumer | D30: =Cases_Raw!F30 -> 1266 | E30: =Cases_Raw!G30 -> 1289 | F30: =(E30-D30)/D30 -> 0.018167457 | G30: =Cases_Raw!J30 -> 518200 | H30: =Cases_Raw!K30 -> 550900 | I30: =(H30-G30)/G30 -> 0.063103049 | J30: =E30*_xlfn.XLOOKUP(A30,Cases[Case_ID],Cases[Standard_Rate]) -> 547825 | K30: =H30/J30 -> 1.0056131 | L30: =Cases_Raw!I30 -> 235 | M30: =E30*L30 -> 302915 | N30: =H30-M30 -> 247985 | O30: =N30/H30 -> 0.45014522 | Q30: =Invoices_Raw!A30 -> INV029 | R30: =Invoices_Raw!B30 -> C017 | S30: =Invoices_Raw!C30 -> Delta Retail | T30: =Invoices_Raw!D30 -> 45759 | U30: =Invoices_Raw!E30 -> 237300 | V30: =Invoices_Raw!F30 -> 45804 | W30: =IF(V30="","Unpaid","Paid") -> Paid | X30: =IF(V30<>"",V30-T30,Summary!$B$1-T30) -> 45 | Y30: =IF(X30<=30,"0-30", IF(X30<=60,"31-60", IF(X30<=90,"61-90","90+"))) -> 31-60
A31: =Cases_Raw!A31 -> C030 | B31: =Cases_Raw!B31 -> Delta Retail | C31: =Cases_Raw!C31 -> Financial Services | D31: =Cases_Raw!F31 -> 897 | E31: =Cases_Raw!G31 -> 921 | F31: =(E31-D31)/D31 -> 0.026755853 | G31: =Cases_Raw!J31 -> 406000 | H31: =Cases_Raw!K31 -> 439300 | I31: =(H31-G31)/G31 -> 0.082019704 | J31: =E31*_xlfn.XLOOKUP(A31,Cases[Case_ID],Cases[Standard_Rate]) -> 437475 | K31: =H31/J31 -> 1.0041717 | L31: =Cases_Raw!I31 -> 250 | M31: =E31*L31 -> 230250 | N31: =H31-M31 -> 209050 | O31: =N31/H31 -> 0.4758707 | Q31: =Invoices_Raw!A31 -> INV030 | R31: =Invoices_Raw!B31 -> C001 | S31: =Invoices_Raw!C31 -> Alpha Health | T31: =Invoices_Raw!D31 -> 45703 | U31: =Invoices_Raw!E31 -> 332200 | V31: =Invoices_Raw!F31 -> 45817 | W31: =IF(V31="","Unpaid","Paid") -> Paid | X31: =IF(V31<>"",V31-T31,Summary!$B$1-T31) -> 114 | Y31: =IF(X31<=30,"0-30", IF(X31<=60,"31-60", IF(X31<=90,"61-90","90+"))) -> 90+
Q32: =Invoices_Raw!A32 -> INV031 | R32: =Invoices_Raw!B32 -> C016 | S32: =Invoices_Raw!C32 -> Epsilon Tech | T32: =Invoices_Raw!D32 -> 45865 | U32: =Invoices_Raw!E32 -> 269500 | V32: =Invoices_Raw!F32 -> 45937 | W32: =IF(V32="","Unpaid","Paid") -> Paid | X32: =IF(V32<>"",V32-T32,Summary!$B$1-T32) -> 72 | Y32: =IF(X32<=30,"0-30", IF(X32<=60,"31-60", IF(X32<=90,"61-90","90+"))) -> 61-90
Q33: =Invoices_Raw!A33 -> INV032 | R33: =Invoices_Raw!B33 -> C012 | S33: =Invoices_Raw!C33 -> Eta Consumer | T33: =Invoices_Raw!D33 -> 46119 | U33: =Invoices_Raw!E33 -> 292400 | V33: =Invoices_Raw!F33 -> 46152 | W33: =IF(V33="","Unpaid","Paid") -> Paid | X33: =IF(V33<>"",V33-T33,Summary!$B$1-T33) -> 33 | Y33: =IF(X33<=30,"0-30", IF(X33<=60,"31-60", IF(X33<=90,"61-90","90+"))) -> 31-60
Q34: =Invoices_Raw!A34 -> INV033 | R34: =Invoices_Raw!B34 -> C027 | S34: =Invoices_Raw!C34 -> Zeta Financial | T34: =Invoices_Raw!D34 -> 45941 | U34: =Invoices_Raw!E34 -> 370800 | W34: =IF(V34="","Unpaid","Paid") -> Unpaid | X34: =IF(V34<>"",V34-T34,Summary!$B$1-T34) -> 446 | Y34: =IF(X34<=30,"0-30", IF(X34<=60,"31-60", IF(X34<=90,"61-90","90+"))) -> 90+
Q35: =Invoices_Raw!A35 -> INV034 | R35: =Invoices_Raw!B35 -> C019 | S35: =Invoices_Raw!C35 -> Theta Health | T35: =Invoices_Raw!D35 -> 45682 | U35: =Invoices_Raw!E35 -> 138600 | V35: =Invoices_Raw!F35 -> 45728 | W35: =IF(V35="","Unpaid","Paid") -> Paid | X35: =IF(V35<>"",V35-T35,Summary!$B$1-T35) -> 46 | Y35: =IF(X35<=30,"0-30", IF(X35<=60,"31-60", IF(X35<=90,"61-90","90+"))) -> 31-60
Q36: =Invoices_Raw!A36 -> INV035 | R36: =Invoices_Raw!B36 -> C022 | S36: =Invoices_Raw!C36 -> Epsilon Tech | T36: =Invoices_Raw!D36 -> 46151 | U36: =Invoices_Raw!E36 -> 336200 | W36: =IF(V36="","Unpaid","Paid") -> Unpaid | X36: =IF(V36<>"",V36-T36,Summary!$B$1-T36) -> 236 | Y36: =IF(X36<=30,"0-30", IF(X36<=60,"31-60", IF(X36<=90,"61-90","90+"))) -> 90+
Q37: =Invoices_Raw!A37 -> INV036 | R37: =Invoices_Raw!B37 -> C023 | S37: =Invoices_Raw!C37 -> Beta Bank | T37: =Invoices_Raw!D37 -> 46073 | U37: =Invoices_Raw!E37 -> 259100 | V37: =Invoices_Raw!F37 -> 46143 | W37: =IF(V37="","Unpaid","Paid") -> Paid | X37: =IF(V37<>"",V37-T37,Summary!$B$1-T37) -> 70 | Y37: =IF(X37<=30,"0-30", IF(X37<=60,"31-60", IF(X37<=90,"61-90","90+"))) -> 61-90
Q38: =Invoices_Raw!A38 -> INV037 | R38: =Invoices_Raw!B38 -> C022 | S38: =Invoices_Raw!C38 -> Epsilon Tech | T38: =Invoices_Raw!D38 -> 46155 | U38: =Invoices_Raw!E38 -> 332600 | V38: =Invoices_Raw!F38 -> 46174 | W38: =IF(V38="","Unpaid","Paid") -> Paid | X38: =IF(V38<>"",V38-T38,Summary!$B$1-T38) -> 19 | Y38: =IF(X38<=30,"0-30", IF(X38<=60,"31-60", IF(X38<=90,"61-90","90+"))) -> 0-30
Q39: =Invoices_Raw!A39 -> INV038 | R39: =Invoices_Raw!B39 -> C014 | S39: =Invoices_Raw!C39 -> Gamma Energy | T39: =Invoices_Raw!D39 -> 46188 | U39: =Invoices_Raw!E39 -> 394100 | V39: =Invoices_Raw!F39 -> 46247 | W39: =IF(V39="","Unpaid","Paid") -> Paid | X39: =IF(V39<>"",V39-T39,Summary!$B$1-T39) -> 59 | Y39: =IF(X39<=30,"0-30", IF(X39<=60,"31-60", IF(X39<=90,"61-90","90+"))) -> 31-60
Q40: =Invoices_Raw!A40 -> INV039 | R40: =Invoices_Raw!B40 -> C030 | S40: =Invoices_Raw!C40 -> Delta Retail | T40: =Invoices_Raw!D40 -> 45910 | U40: =Invoices_Raw!E40 -> 201100 | V40: =Invoices_Raw!F40 -> 45928 | W40: =IF(V40="","Unpaid","Paid") -> Paid | X40: =IF(V40<>"",V40-T40,Summary!$B$1-T40) -> 18 | Y40: =IF(X40<=30,"0-30", IF(X40<=60,"31-60", IF(X40<=90,"61-90","90+"))) -> 0-30
Q41: =Invoices_Raw!A41 -> INV040 | R41: =Invoices_Raw!B41 -> C006 | S41: =Invoices_Raw!C41 -> Theta Health | T41: =Invoices_Raw!D41 -> 45701 | U41: =Invoices_Raw!E41 -> 172500 | V41: =Invoices_Raw!F41 -> 45731 | W41: =IF(V41="","Unpaid","Paid") -> Paid | X41: =IF(V41<>"",V41-T41,Summary!$B$1-T41) -> 30 | Y41: =IF(X41<=30,"0-30", IF(X41<=60,"31-60", IF(X41<=90,"61-90","90+"))) -> 0-30
Q42: =Invoices_Raw!A42 -> INV041 | R42: =Invoices_Raw!B42 -> C006 | S42: =Invoices_Raw!C42 -> Theta Health | T42: =Invoices_Raw!D42 -> 45697 | U42: =Invoices_Raw!E42 -> 208200 | V42: =Invoices_Raw!F42 -> 45735 | W42: =IF(V42="","Unpaid","Paid") -> Paid | X42: =IF(V42<>"",V42-T42,Summary!$B$1-T42) -> 38 | Y42: =IF(X42<=30,"0-30", IF(X42<=60,"31-60", IF(X42<=90,"61-90","90+"))) -> 31-60
Q43: =Invoices_Raw!A43 -> INV042 | R43: =Invoices_Raw!B43 -> C013 | S43: =Invoices_Raw!C43 -> Gamma Energy | T43: =Invoices_Raw!D43 -> 46094 | U43: =Invoices_Raw!E43 -> 340800 | V43: =Invoices_Raw!F43 -> 46124 | W43: =IF(V43="","Unpaid","Paid") -> Paid | X43: =IF(V43<>"",V43-T43,Summary!$B$1-T43) -> 30 | Y43: =IF(X43<=30,"0-30", IF(X43<=60,"31-60", IF(X43<=90,"61-90","90+"))) -> 0-30
Q44: =Invoices_Raw!A44 -> INV043 | R44: =Invoices_Raw!B44 -> C019 | S44: =Invoices_Raw!C44 -> Theta Health | T44: =Invoices_Raw!D44 -> 45660 | U44: =Invoices_Raw!E44 -> 143500 | V44: =Invoices_Raw!F44 -> 45729 | W44: =IF(V44="","Unpaid","Paid") -> Paid | X44: =IF(V44<>"",V44-T44,Summary!$B$1-T44) -> 69 | Y44: =IF(X44<=30,"0-30", IF(X44<=60,"31-60", IF(X44<=90,"61-90","90+"))) -> 61-90
Q45: =Invoices_Raw!A45 -> INV044 | R45: =Invoices_Raw!B45 -> C022 | S45: =Invoices_Raw!C45 -> Epsilon Tech | T45: =Invoices_Raw!D45 -> 46159 | U45: =Invoices_Raw!E45 -> 342200 | V45: =Invoices_Raw!F45 -> 46175 | W45: =IF(V45="","Unpaid","Paid") -> Paid | X45: =IF(V45<>"",V45-T45,Summary!$B$1-T45) -> 16 | Y45: =IF(X45<=30,"0-30", IF(X45<=60,"31-60", IF(X45<=90,"61-90","90+"))) -> 0-30
Q46: =Invoices_Raw!A46 -> INV045 | R46: =Invoices_Raw!B46 -> C008 | S46: =Invoices_Raw!C46 -> Epsilon Tech | T46: =Invoices_Raw!D46 -> 46019 | U46: =Invoices_Raw!E46 -> 123100 | V46: =Invoices_Raw!F46 -> 46082 | W46: =IF(V46="","Unpaid","Paid") -> Paid | X46: =IF(V46<>"",V46-T46,Summary!$B$1-T46) -> 63 | Y46: =IF(X46<=30,"0-30", IF(X46<=60,"31-60", IF(X46<=90,"61-90","90+"))) -> 61-90
...

Sheet Summary
A1: Reporting Date | B1: 46387
A3: Average DSO | B3: =AVERAGEIF(Calculations!W2:W61,"Paid",Calculations!X2:X61) -> 60.387755
A5: Total Fees | B5: Gross Margin | C5: Average Realization | D5: Average DSO
A6: =SUM(Calculations!H2:H31) -> 16394500 | B6: =SUM(Calculations!N2:N31)/SUM(Calculations!H2:H31) -> 0.41963128 | C6: =AVERAGE(Calculations!K2:K31) -> 0.94394287 | D6: =AVERAGEIF( Calculations!W2:W61, "Paid", Calculations!X2:X61 ) -> 60.387755
A8: Practice Area | B8: Gross Margin | D8: Case | E8: Client | F8: Practice Area | G8: Hours Variance
A9: Financial Services | B9: =SUMIF( Calculations!$C$2:$C$31, A9, Calculations!$N$2:$N$31 ) / SUMIF( Calculations!$C$2:$C$31, A9, Calculations!$H$2:$H$31 ) -> 0.45633638 | D9: {=_xlfn.TAKE( _xlfn.SORTBY( Calculations!A2:F31, Calculations!F2:F31, -1 ), 10 )} -> C001 | E9: Alpha Health | F9: Financial Services | G9: 1092 | H9: 1441 | I9: 0.31959707
A10: Healthcare | B10: =SUMIF( Calculations!$C$2:$C$31, A10, Calculations!$N$2:$N$31 ) / SUMIF( Calculations!$C$2:$C$31, A10, Calculations!$H$2:$H$31 ) -> 0.33829174 | D10: C005 | E10: Gamma Energy | F10: Healthcare | G10: 878 | H10: 1134 | I10: 0.29157175
A11: Consumer | B11: =SUMIF( Calculations!$C$2:$C$31, A11, Calculations!$N$2:$N$31 ) / SUMIF( Calculations!$C$2:$C$31, A11, Calculations!$H$2:$H$31 ) -> 0.42761567 | D11: C020 | E11: Gamma Energy | F11: Healthcare | G11: 1183 | H11: 1485 | I11: 0.25528318
A12: Technology | B12: =SUMIF( Calculations!$C$2:$C$31, A12, Calculations!$N$2:$N$31 ) / SUMIF( Calculations!$C$2:$C$31, A12, Calculations!$H$2:$H$31 ) -> 0.43493889 | D12: C019 | E12: Theta Health | F12: Healthcare | G12: 598 | H12: 734 | I12: 0.22742475
D13: C022 | E13: Epsilon Tech | F13: Healthcare | G13: 1460 | H13: 1759 | I13: 0.20479452
D14: C004 | E14: Alpha Health | F14: Healthcare | G14: 788 | H14: 946 | I14: 0.20050761
A15: Key Finding | D15: C013 | E15: Gamma Energy | F15: Healthcare | G15: 1429 | H15: 1713 | I15: 0.19874038
A16: Healthcare has the highest average hours overrun and lower realization, indicating potential margin leakage. | D16: C025 | E16: Delta Retail | F16: Consumer | G16: 1142 | H16: 1315 | I16: 0.15148862
D17: C016 | E17: Epsilon Tech | F17: Technology | G17: 1002 | H17: 1145 | I17: 0.14271457
D18: C006 | E18: Theta Health | F18: Financial Services | G18: 730 | H18: 827 | I18: 0.13287671
A20: Aging Bucket | B20: Outstanding Amount
A21: 0–30 | B21: =SUMIF( Calculations!$Y$2:$Y$61, A20, Calculations!$U$2:$U$61 ) -> 0
A22: 31–60 | B22: =SUMIF( Calculations!$Y$2:$Y$61, A21, Calculations!$U$2:$U$61 ) -> 0
A23: 61–90 | B23: =SUMIF( Calculations!$Y$2:$Y$61, A22, Calculations!$U$2:$U$61 ) -> 0
A24: 90+ | B24: =SUMIF( Calculations!$Y$2:$Y$61, A23, Calculations!$U$2:$U$61 ) -> 0
